{
 "cells": [
  {
   "cell_type": "markdown",
   "metadata": {},
   "source": [
    "# Exception Handling in Python"
   ]
  },
  {
   "cell_type": "markdown",
   "metadata": {},
   "source": [
    "## Objectives\n",
    "\n",
    "1. Understanding Exceptions\n",
    "2. Distinguishing Errors from Exceptions\n",
    "3. Familiarity with Common Python Exceptions\n",
    "4. Managing Exeptions Effectively\n",
    "\n",
    "In the world of programming, errors and enexpected situations are certain. Python, a popular and versatile programming language, equips developers with a powerful toolset to manage these unforeseen scenarios through exceptions and error handling."
   ]
  },
  {
   "cell_type": "markdown",
   "metadata": {},
   "source": [
    "## What are exceptions?\n",
    "\n",
    "**Exceptions** are alerts when something unexpected happens while running a program. It could be a mistake in the code or a situation that was not planned for. Python can raise these alerts automatically, but we can also tigger them on purpose using the raise command. The cool part is that we can prevert our program from crashing by handling exceptions.\n"
   ]
  },
  {
   "cell_type": "markdown",
   "metadata": {},
   "source": [
    "## Errrors vs Exceptions\n",
    "\n",
    "Hold on, what is the difference between errors and exceptions? Well, `errors` are usually big problems that come from the computer or the system. They often make the program stop working completely. On the other hand, `exceptions` are more like issues we can control. They happen because of something we did in our code  and can usually be fixed, so the program keeps going.\n",
    "\n",
    "Here is the difference between `Errors and exceptions`\n",
    "\n",
    "| Aspect | Errors | Exeptions|\n",
    "|---|---|---|\n",
    "|Origin| Errors are typically caused by the environment, hardware, or operating system| Exceptions are usually a result of problematic code execution within the program|\n",
    "|Nature| Errors are often severe and can lead to program crashes or abnormal termination. | Exceptions are generally less severe and can be caught and handled to prevent program termination| \n",
    "|Handling| Errors are not usually caught or handled by the program itself| Exceptions can be caught using try-except blocks and dealt with gracefully, allowing the program to continue execution|\n",
    "|Examples| Examples include \"SyntaxError\" due to incorrect syntax or \"NameError\" when a variable is not defined| Examples include \"ZeroDivisionError\" When dividing by zero, or \"FileNotFoundError\" when attempting to open a non-existent file.|\n",
    "|Categorization | Errors are not classified into categories| Exceptions are categorized into various classes, such as \"ArithmeticError\" , \"IOError\", \"ValueError\" etc, based on their nature.|\n"
   ]
  },
  {
   "cell_type": "markdown",
   "metadata": {},
   "source": [
    "## Common Exceptions in Python\n",
    "\n",
    "Here are a few examples of exceptions we often run into and can handle using this tool:\n",
    "\n",
    "**ZeroDivisionError**: This error arises when an attempt is made to divide a number by zero. Division by zero is undefined in mathematics, causing an arithmetic error. For instance: For example:"
   ]
  },
  {
   "cell_type": "code",
   "execution_count": 1,
   "metadata": {},
   "outputs": [
    {
     "ename": "ZeroDivisionError",
     "evalue": "division by zero",
     "output_type": "error",
     "traceback": [
      "\u001b[0;31m---------------------------------------------------------------------------\u001b[0m",
      "\u001b[0;31mZeroDivisionError\u001b[0m                         Traceback (most recent call last)",
      "Cell \u001b[0;32mIn[1], line 1\u001b[0m\n\u001b[0;32m----> 1\u001b[0m result \u001b[38;5;241m=\u001b[39m \u001b[38;5;241;43m10\u001b[39;49m\u001b[43m \u001b[49m\u001b[38;5;241;43m/\u001b[39;49m\u001b[43m \u001b[49m\u001b[38;5;241;43m0\u001b[39;49m\n\u001b[1;32m      2\u001b[0m \u001b[38;5;28mprint\u001b[39m(result)\n\u001b[1;32m      4\u001b[0m \u001b[38;5;66;03m# Raises ZeroDivisionError\u001b[39;00m\n",
      "\u001b[0;31mZeroDivisionError\u001b[0m: division by zero"
     ]
    }
   ],
   "source": [
    "result = 10 / 0\n",
    "print(result)\n",
    "\n",
    "# Raises ZeroDivisionError\n"
   ]
  },
  {
   "cell_type": "markdown",
   "metadata": {},
   "source": [
    "**ValueError**: This error occurs when an inappropriate value is used within the code. An example of this is when trying to convert a non-numeric string to an integer: \n",
    "\n",
    "For example:"
   ]
  },
  {
   "cell_type": "code",
   "execution_count": null,
   "metadata": {},
   "outputs": [
    {
     "ename": "FileNotFoundError",
     "evalue": "[Errno 2] No such file or directory: 'nonExistentFile.txt'",
     "output_type": "error",
     "traceback": [
      "\u001b[0;31m---------------------------------------------------------------------------\u001b[0m",
      "\u001b[0;31mFileNotFoundError\u001b[0m                         Traceback (most recent call last)",
      "Cell \u001b[0;32mIn[2], line 1\u001b[0m\n\u001b[0;32m----> 1\u001b[0m \u001b[38;5;28;01mwith\u001b[39;00m \u001b[38;5;28;43mopen\u001b[39;49m\u001b[43m(\u001b[49m\u001b[38;5;124;43m'\u001b[39;49m\u001b[38;5;124;43mnonExistentFile.txt\u001b[39;49m\u001b[38;5;124;43m'\u001b[39;49m\u001b[43m,\u001b[49m\u001b[43m \u001b[49m\u001b[38;5;124;43m'\u001b[39;49m\u001b[38;5;124;43mr\u001b[39;49m\u001b[38;5;124;43m'\u001b[39;49m\u001b[43m)\u001b[49m \u001b[38;5;28;01mas\u001b[39;00m file:\n\u001b[1;32m      2\u001b[0m \tcontent \u001b[38;5;241m=\u001b[39m file\u001b[38;5;241m.\u001b[39mread()\n",
      "File \u001b[0;32m~/.local/lib/python3.10/site-packages/IPython/core/interactiveshell.py:324\u001b[0m, in \u001b[0;36m_modified_open\u001b[0;34m(file, *args, **kwargs)\u001b[0m\n\u001b[1;32m    317\u001b[0m \u001b[38;5;28;01mif\u001b[39;00m file \u001b[38;5;129;01min\u001b[39;00m {\u001b[38;5;241m0\u001b[39m, \u001b[38;5;241m1\u001b[39m, \u001b[38;5;241m2\u001b[39m}:\n\u001b[1;32m    318\u001b[0m     \u001b[38;5;28;01mraise\u001b[39;00m \u001b[38;5;167;01mValueError\u001b[39;00m(\n\u001b[1;32m    319\u001b[0m         \u001b[38;5;124mf\u001b[39m\u001b[38;5;124m\"\u001b[39m\u001b[38;5;124mIPython won\u001b[39m\u001b[38;5;124m'\u001b[39m\u001b[38;5;124mt let you open fd=\u001b[39m\u001b[38;5;132;01m{\u001b[39;00mfile\u001b[38;5;132;01m}\u001b[39;00m\u001b[38;5;124m by default \u001b[39m\u001b[38;5;124m\"\u001b[39m\n\u001b[1;32m    320\u001b[0m         \u001b[38;5;124m\"\u001b[39m\u001b[38;5;124mas it is likely to crash IPython. If you know what you are doing, \u001b[39m\u001b[38;5;124m\"\u001b[39m\n\u001b[1;32m    321\u001b[0m         \u001b[38;5;124m\"\u001b[39m\u001b[38;5;124myou can use builtins\u001b[39m\u001b[38;5;124m'\u001b[39m\u001b[38;5;124m open.\u001b[39m\u001b[38;5;124m\"\u001b[39m\n\u001b[1;32m    322\u001b[0m     )\n\u001b[0;32m--> 324\u001b[0m \u001b[38;5;28;01mreturn\u001b[39;00m \u001b[43mio_open\u001b[49m\u001b[43m(\u001b[49m\u001b[43mfile\u001b[49m\u001b[43m,\u001b[49m\u001b[43m \u001b[49m\u001b[38;5;241;43m*\u001b[39;49m\u001b[43margs\u001b[49m\u001b[43m,\u001b[49m\u001b[43m \u001b[49m\u001b[38;5;241;43m*\u001b[39;49m\u001b[38;5;241;43m*\u001b[39;49m\u001b[43mkwargs\u001b[49m\u001b[43m)\u001b[49m\n",
      "\u001b[0;31mFileNotFoundError\u001b[0m: [Errno 2] No such file or directory: 'nonExistentFile.txt'"
     ]
    }
   ],
   "source": [
    "with open('nonExistentFile.txt', 'r') as file:\n",
    "\tcontent = file.read()"
   ]
  },
  {
   "cell_type": "markdown",
   "metadata": {},
   "source": [
    "FileNotFoundError: This exception is encountered when an attempt is made to access a file that does not exist. \n",
    "\n",
    "For example:\n"
   ]
  },
  {
   "cell_type": "markdown",
   "metadata": {},
   "source": [
    "**KeyError**: The keyError arises when an attempt is made to access a non-existent key in a dictionary. \n",
    "\n",
    "For example:\n"
   ]
  },
  {
   "cell_type": "code",
   "execution_count": null,
   "metadata": {},
   "outputs": [
    {
     "ename": "IndexError",
     "evalue": "list index out of range",
     "output_type": "error",
     "traceback": [
      "\u001b[0;31m---------------------------------------------------------------------------\u001b[0m",
      "\u001b[0;31mIndexError\u001b[0m                                Traceback (most recent call last)",
      "Cell \u001b[0;32mIn[3], line 3\u001b[0m\n\u001b[1;32m      1\u001b[0m my_list \u001b[38;5;241m=\u001b[39m [\u001b[38;5;241m1\u001b[39m, \u001b[38;5;241m2\u001b[39m, \u001b[38;5;241m3\u001b[39m]\n\u001b[1;32m      2\u001b[0m value \u001b[38;5;241m=\u001b[39m my_list[\u001b[38;5;241m1\u001b[39m] \u001b[38;5;66;03m# No IndexError, within range \u001b[39;00m\n\u001b[0;32m----> 3\u001b[0m missing \u001b[38;5;241m=\u001b[39m \u001b[43mmy_list\u001b[49m\u001b[43m[\u001b[49m\u001b[38;5;241;43m5\u001b[39;49m\u001b[43m]\u001b[49m\n",
      "\u001b[0;31mIndexError\u001b[0m: list index out of range"
     ]
    }
   ],
   "source": [
    "my_list = [1, 2, 3]\n",
    "value = my_list[1] # No IndexError, within range \n",
    "missing = my_list[5] # Raises IndexError"
   ]
  },
  {
   "cell_type": "markdown",
   "metadata": {},
   "source": [
    "**KeyError**: The KeyError arises when an attempt is made to access a non-existent key in a dictionary\n",
    "\n",
    "For example:"
   ]
  },
  {
   "cell_type": "code",
   "execution_count": null,
   "metadata": {},
   "outputs": [
    {
     "ename": "KeyError",
     "evalue": "'city'",
     "output_type": "error",
     "traceback": [
      "\u001b[0;31m---------------------------------------------------------------------------\u001b[0m",
      "\u001b[0;31mKeyError\u001b[0m                                  Traceback (most recent call last)",
      "Cell \u001b[0;32mIn[2], line 3\u001b[0m\n\u001b[1;32m      1\u001b[0m my_dict \u001b[38;5;241m=\u001b[39m {\u001b[38;5;124m'\u001b[39m\u001b[38;5;124mname\u001b[39m\u001b[38;5;124m'\u001b[39m : \u001b[38;5;124m'\u001b[39m\u001b[38;5;124malice\u001b[39m\u001b[38;5;124m'\u001b[39m, \u001b[38;5;124m'\u001b[39m\u001b[38;5;124mage\u001b[39m\u001b[38;5;124m'\u001b[39m: \u001b[38;5;241m30\u001b[39m}\n\u001b[1;32m      2\u001b[0m value \u001b[38;5;241m=\u001b[39m my_dict\u001b[38;5;241m.\u001b[39mget(\u001b[38;5;124m'\u001b[39m\u001b[38;5;124mcity\u001b[39m\u001b[38;5;124m'\u001b[39m)\n\u001b[0;32m----> 3\u001b[0m missing \u001b[38;5;241m=\u001b[39m \u001b[43mmy_dict\u001b[49m\u001b[43m[\u001b[49m\u001b[38;5;124;43m'\u001b[39;49m\u001b[38;5;124;43mcity\u001b[39;49m\u001b[38;5;124;43m'\u001b[39;49m\u001b[43m]\u001b[49m\n",
      "\u001b[0;31mKeyError\u001b[0m: 'city'"
     ]
    }
   ],
   "source": [
    "my_dict = {'name' : 'alice', 'age': 30}\n",
    "value = my_dict.get('city') # No k\n",
    "missing = my_dict['city']"
   ]
  },
  {
   "cell_type": "markdown",
   "metadata": {},
   "source": [
    "**TypeError**: The TypeError occurs when a n object is used in an incompatible manner. An example includes trying to concatenate a string and an integer:\n",
    "\n",
    "For example:"
   ]
  },
  {
   "cell_type": "code",
   "execution_count": 3,
   "metadata": {},
   "outputs": [
    {
     "ename": "TypeError",
     "evalue": "can only concatenate str (not \"int\") to str",
     "output_type": "error",
     "traceback": [
      "\u001b[0;31m---------------------------------------------------------------------------\u001b[0m",
      "\u001b[0;31mTypeError\u001b[0m                                 Traceback (most recent call last)",
      "Cell \u001b[0;32mIn[3], line 1\u001b[0m\n\u001b[0;32m----> 1\u001b[0m result \u001b[38;5;241m=\u001b[39m \u001b[38;5;124;43m'\u001b[39;49m\u001b[38;5;124;43mHello\u001b[39;49m\u001b[38;5;124;43m'\u001b[39;49m\u001b[43m  \u001b[49m\u001b[38;5;241;43m+\u001b[39;49m\u001b[43m \u001b[49m\u001b[38;5;241;43m5\u001b[39;49m\n\u001b[1;32m      2\u001b[0m \u001b[38;5;66;03m# Raises TypeError\u001b[39;00m\n",
      "\u001b[0;31mTypeError\u001b[0m: can only concatenate str (not \"int\") to str"
     ]
    }
   ],
   "source": [
    "result = 'Hello'  + 5\n",
    "# Raises TypeError"
   ]
  },
  {
   "cell_type": "markdown",
   "metadata": {},
   "source": [
    "**AttributeError**: An AttributeError occurs when a attribute or method is accessed on an object that doesn't possess that specific attribute or method. For instance:\n",
    "\n",
    "For example:"
   ]
  },
  {
   "cell_type": "code",
   "execution_count": 4,
   "metadata": {},
   "outputs": [
    {
     "ename": "AttributeError",
     "evalue": "'str' object has no attribute 'some_method'",
     "output_type": "error",
     "traceback": [
      "\u001b[0;31m---------------------------------------------------------------------------\u001b[0m",
      "\u001b[0;31mAttributeError\u001b[0m                            Traceback (most recent call last)",
      "Cell \u001b[0;32mIn[4], line 3\u001b[0m\n\u001b[1;32m      1\u001b[0m text \u001b[38;5;241m=\u001b[39m \u001b[38;5;124m'\u001b[39m\u001b[38;5;124mexample\u001b[39m\u001b[38;5;124m'\u001b[39m\n\u001b[1;32m      2\u001b[0m length \u001b[38;5;241m=\u001b[39m \u001b[38;5;28mlen\u001b[39m(text) \u001b[38;5;66;03m# No AttributeError, correct method usage\u001b[39;00m\n\u001b[0;32m----> 3\u001b[0m missign \u001b[38;5;241m=\u001b[39m \u001b[43mtext\u001b[49m\u001b[38;5;241;43m.\u001b[39;49m\u001b[43msome_method\u001b[49m() \u001b[38;5;66;03m# Raises AttributeError\u001b[39;00m\n",
      "\u001b[0;31mAttributeError\u001b[0m: 'str' object has no attribute 'some_method'"
     ]
    }
   ],
   "source": [
    "text = 'example'\n",
    "length = len(text) # No AttributeError, correct method usage\n",
    "missign = text.some_method() # Raises AttributeError\n"
   ]
  },
  {
   "cell_type": "markdown",
   "metadata": {},
   "source": [
    "**AtributeError**: An AttributeError occurs when an attribute or method is accessed on an object that doesn't possess that specific attribute or method. For instance:\n",
    "\n",
    "For example:\n"
   ]
  },
  {
   "cell_type": "code",
   "execution_count": 6,
   "metadata": {},
   "outputs": [
    {
     "ename": "AttributeError",
     "evalue": "'str' object has no attribute 'some_method'",
     "output_type": "error",
     "traceback": [
      "\u001b[0;31m---------------------------------------------------------------------------\u001b[0m",
      "\u001b[0;31mAttributeError\u001b[0m                            Traceback (most recent call last)",
      "Cell \u001b[0;32mIn[6], line 3\u001b[0m\n\u001b[1;32m      1\u001b[0m text \u001b[38;5;241m=\u001b[39m \u001b[38;5;124m'\u001b[39m\u001b[38;5;124mExample\u001b[39m\u001b[38;5;124m'\u001b[39m\n\u001b[1;32m      2\u001b[0m length \u001b[38;5;241m=\u001b[39m \u001b[38;5;28mlen\u001b[39m(text) \u001b[38;5;66;03m# No AttributeError, correct method usage\u001b[39;00m\n\u001b[0;32m----> 3\u001b[0m missing \u001b[38;5;241m=\u001b[39m \u001b[43mtext\u001b[49m\u001b[38;5;241;43m.\u001b[39;49m\u001b[43msome_method\u001b[49m() \u001b[38;5;66;03m# Raises AttributeError\u001b[39;00m\n",
      "\u001b[0;31mAttributeError\u001b[0m: 'str' object has no attribute 'some_method'"
     ]
    }
   ],
   "source": [
    "text = 'Example'\n",
    "length = len(text) # No AttributeError, correct method usage\n",
    "missing = text.some_method() # Raises AttributeError"
   ]
  },
  {
   "cell_type": "markdown",
   "metadata": {},
   "source": [
    "**ImportError**: This error is encountered when an attempt is made to import a module that is unavailable. For example `import non_existent_module`\n",
    "\n",
    "> *NOTE*: Please remember, the exceptions you will encounter are not limited to just these. There are many more in Python. However, there is no need to woory. By using the teachnique provided below and following the correct syntax, you will be able to handle any exceptions that come your way."
   ]
  },
  {
   "cell_type": "markdown",
   "metadata": {},
   "source": [
    "## Handling Exceptions:\n",
    "\n",
    "Python has a handy tool called `try and except` that help us manage exceptions.\n",
    "\n",
    "**Try and Except**: You can use the try and except blocks to prevent your program from crashing due to exceptions.\n",
    "\n",
    "Here's how they work:\n",
    "\n",
    "1. The code that may result in an exception is contained in the try block.\n",
    "2. If an exception occurs, the code directly jumps to except block.\n",
    "3. In the except block, you can define how to handle the exception gracefully, like displaying an error message or taking alternative actions.\n",
    "4. After the except block, the program continues executing the remaining code.\n"
   ]
  },
  {
   "cell_type": "markdown",
   "metadata": {},
   "source": [
    "### Example: Attempting to divide by zero\n"
   ]
  },
  {
   "cell_type": "code",
   "execution_count": 7,
   "metadata": {},
   "outputs": [
    {
     "name": "stdout",
     "output_type": "stream",
     "text": [
      "Error: cannot divide by zero\n",
      "outside of try and except block\n"
     ]
    }
   ],
   "source": [
    "# using Try - except\n",
    "try: \n",
    "\t# Attempting to divide 10 by 0\n",
    "\tresult = 10 / 0\n",
    "\n",
    "except ZeroDivisionError:\n",
    "\t\t# Handling the ZeroDivisionError and printing an error message\n",
    "\t\tprint('Error: cannot divide by zero')\n",
    "\t\n",
    "# This line will be executed regardless of whether an exception occurred\n",
    "print('outside of try and except block')\n"
   ]
  }
 ],
 "metadata": {
  "kernelspec": {
   "display_name": "Python 3",
   "language": "python",
   "name": "python3"
  },
  "language_info": {
   "codemirror_mode": {
    "name": "ipython",
    "version": 3
   },
   "file_extension": ".py",
   "mimetype": "text/x-python",
   "name": "python",
   "nbconvert_exporter": "python",
   "pygments_lexer": "ipython3",
   "version": "3.10.12"
  }
 },
 "nbformat": 4,
 "nbformat_minor": 2
}
